[2024-05-08T00:23:17.412+0000] {local_task_job_runner.py:120} INFO - ::group::Pre task execution logs
[2024-05-08T00:23:17.435+0000] {taskinstance.py:2076} INFO - Dependencies all met for dep_context=non-requeueable deps ti=<TaskInstance: 6.1_monitoring.tarea2 scheduled__2024-01-19T00:00:00+00:00 [queued]>
[2024-05-08T00:23:17.447+0000] {taskinstance.py:2076} INFO - Dependencies all met for dep_context=requeueable deps ti=<TaskInstance: 6.1_monitoring.tarea2 scheduled__2024-01-19T00:00:00+00:00 [queued]>
[2024-05-08T00:23:17.448+0000] {taskinstance.py:2306} INFO - Starting attempt 1 of 1
[2024-05-08T00:23:17.466+0000] {taskinstance.py:2330} INFO - Executing <Task(BashOperator): tarea2> on 2024-01-19 00:00:00+00:00
[2024-05-08T00:23:17.473+0000] {warnings.py:110} WARNING - /home/***/.local/lib/python3.12/site-packages/***/task/task_runner/standard_task_runner.py:61: DeprecationWarning: This process (pid=4415) is multi-threaded, use of fork() may lead to deadlocks in the child.
  pid = os.fork()

[2024-05-08T00:23:17.475+0000] {standard_task_runner.py:63} INFO - Started process 4421 to run task
[2024-05-08T00:23:17.474+0000] {standard_task_runner.py:90} INFO - Running: ['***', 'tasks', 'run', '6.1_monitoring', 'tarea2', 'scheduled__2024-01-19T00:00:00+00:00', '--job-id', '334', '--raw', '--subdir', 'DAGS_FOLDER/061_monitoring.py', '--cfg-path', '/tmp/tmp8uhpmrpd']
[2024-05-08T00:23:17.476+0000] {standard_task_runner.py:91} INFO - Job 334: Subtask tarea2
[2024-05-08T00:23:17.531+0000] {task_command.py:426} INFO - Running <TaskInstance: 6.1_monitoring.tarea2 scheduled__2024-01-19T00:00:00+00:00 [running]> on host 521bf890d837
[2024-05-08T00:23:17.625+0000] {taskinstance.py:2648} INFO - Exporting env vars: AIRFLOW_CTX_DAG_OWNER='***' AIRFLOW_CTX_DAG_ID='6.1_monitoring' AIRFLOW_CTX_TASK_ID='tarea2' AIRFLOW_CTX_EXECUTION_DATE='2024-01-19T00:00:00+00:00' AIRFLOW_CTX_TRY_NUMBER='1' AIRFLOW_CTX_DAG_RUN_ID='scheduled__2024-01-19T00:00:00+00:00'
[2024-05-08T00:23:17.626+0000] {taskinstance.py:430} INFO - ::endgroup::
[2024-05-08T00:23:17.639+0000] {subprocess.py:63} INFO - Tmp dir root location: /tmp
[2024-05-08T00:23:17.641+0000] {subprocess.py:75} INFO - Running command: ['/usr/bin/bash', '-c', "sleep 2 && echo 'Segunda tarea!"]
[2024-05-08T00:23:17.652+0000] {subprocess.py:86} INFO - Output:
[2024-05-08T00:23:17.653+0000] {subprocess.py:93} INFO - /usr/bin/bash: -c: line 1: unexpected EOF while looking for matching `''
[2024-05-08T00:23:17.654+0000] {subprocess.py:97} INFO - Command exited with return code 2
[2024-05-08T00:23:17.655+0000] {taskinstance.py:441} INFO - ::group::Post task execution logs
[2024-05-08T00:23:17.667+0000] {taskinstance.py:2905} ERROR - Task failed with exception
Traceback (most recent call last):
  File "/home/airflow/.local/lib/python3.12/site-packages/airflow/models/taskinstance.py", line 465, in _execute_task
    result = _execute_callable(context=context, **execute_callable_kwargs)
             ^^^^^^^^^^^^^^^^^^^^^^^^^^^^^^^^^^^^^^^^^^^^^^^^^^^^^^^^^^^^^
  File "/home/airflow/.local/lib/python3.12/site-packages/airflow/models/taskinstance.py", line 432, in _execute_callable
    return execute_callable(context=context, **execute_callable_kwargs)
           ^^^^^^^^^^^^^^^^^^^^^^^^^^^^^^^^^^^^^^^^^^^^^^^^^^^^^^^^^^^^
  File "/home/airflow/.local/lib/python3.12/site-packages/airflow/models/baseoperator.py", line 400, in wrapper
    return func(self, *args, **kwargs)
           ^^^^^^^^^^^^^^^^^^^^^^^^^^^
  File "/home/airflow/.local/lib/python3.12/site-packages/airflow/operators/bash.py", line 243, in execute
    raise AirflowException(
airflow.exceptions.AirflowException: Bash command failed. The command returned a non-zero exit code 2.
[2024-05-08T00:23:17.672+0000] {taskinstance.py:1206} INFO - Marking task as FAILED. dag_id=6.1_monitoring, task_id=tarea2, run_id=scheduled__2024-01-19T00:00:00+00:00, execution_date=20240119T000000, start_date=20240508T002317, end_date=20240508T002317
[2024-05-08T00:23:17.690+0000] {standard_task_runner.py:110} ERROR - Failed to execute job 334 for task tarea2 (Bash command failed. The command returned a non-zero exit code 2.; 4421)
[2024-05-08T00:23:17.730+0000] {local_task_job_runner.py:240} INFO - Task exited with return code 1
[2024-05-08T00:23:17.757+0000] {taskinstance.py:3498} INFO - 0 downstream tasks scheduled from follow-on schedule check
[2024-05-08T00:23:17.763+0000] {local_task_job_runner.py:222} INFO - ::endgroup::
