[2024-05-10T06:01:29.637+0000] {task_context_logger.py:104} ERROR - Executor reports task instance <TaskInstance: Proyecto_Nasa.esperar_archivo scheduled__2023-11-27T00:00:00+00:00 [queued]> finished (failed) although the task says it's queued. (Info: None) Was the task killed externally?
