[2024-05-08T19:44:16.909+0000] {local_task_job_runner.py:120} INFO - ::group::Pre task execution logs
[2024-05-08T19:44:16.927+0000] {taskinstance.py:2076} INFO - Dependencies all met for dep_context=non-requeueable deps ti=<TaskInstance: 7.3_filesensor.creating_file scheduled__2022-07-09T00:00:00+00:00 [queued]>
[2024-05-08T19:44:16.932+0000] {taskinstance.py:2076} INFO - Dependencies all met for dep_context=requeueable deps ti=<TaskInstance: 7.3_filesensor.creating_file scheduled__2022-07-09T00:00:00+00:00 [queued]>
[2024-05-08T19:44:16.934+0000] {taskinstance.py:2306} INFO - Starting attempt 1 of 1
[2024-05-08T19:44:16.948+0000] {taskinstance.py:2330} INFO - Executing <Task(BashOperator): creating_file> on 2022-07-09 00:00:00+00:00
[2024-05-08T19:44:16.953+0000] {warnings.py:110} WARNING - /home/***/.local/lib/python3.12/site-packages/***/task/task_runner/standard_task_runner.py:61: DeprecationWarning: This process (pid=1930) is multi-threaded, use of fork() may lead to deadlocks in the child.
  pid = os.fork()

[2024-05-08T19:44:16.954+0000] {standard_task_runner.py:90} INFO - Running: ['***', 'tasks', 'run', '7.3_filesensor', 'creating_file', 'scheduled__2022-07-09T00:00:00+00:00', '--job-id', '653', '--raw', '--subdir', 'DAGS_FOLDER/07_FileSensor.py', '--cfg-path', '/tmp/tmp73qjpd_o']
[2024-05-08T19:44:16.955+0000] {standard_task_runner.py:63} INFO - Started process 1931 to run task
[2024-05-08T19:44:16.956+0000] {standard_task_runner.py:91} INFO - Job 653: Subtask creating_file
[2024-05-08T19:44:16.998+0000] {task_command.py:426} INFO - Running <TaskInstance: 7.3_filesensor.creating_file scheduled__2022-07-09T00:00:00+00:00 [running]> on host ccc314eb571d
[2024-05-08T19:44:17.062+0000] {taskinstance.py:2648} INFO - Exporting env vars: AIRFLOW_CTX_DAG_OWNER='***' AIRFLOW_CTX_DAG_ID='7.3_filesensor' AIRFLOW_CTX_TASK_ID='creating_file' AIRFLOW_CTX_EXECUTION_DATE='2022-07-09T00:00:00+00:00' AIRFLOW_CTX_TRY_NUMBER='1' AIRFLOW_CTX_DAG_RUN_ID='scheduled__2022-07-09T00:00:00+00:00'
[2024-05-08T19:44:17.063+0000] {taskinstance.py:430} INFO - ::endgroup::
[2024-05-08T19:44:17.074+0000] {subprocess.py:63} INFO - Tmp dir root location: /tmp
[2024-05-08T19:44:17.075+0000] {subprocess.py:75} INFO - Running command: ['/usr/bin/bash', '-c', "sleep 10 && touch /tmp/file.txt'"]
[2024-05-08T19:44:17.083+0000] {subprocess.py:86} INFO - Output:
[2024-05-08T19:44:17.084+0000] {subprocess.py:93} INFO - /usr/bin/bash: -c: line 1: unexpected EOF while looking for matching `''
[2024-05-08T19:44:17.084+0000] {subprocess.py:97} INFO - Command exited with return code 2
[2024-05-08T19:44:17.085+0000] {taskinstance.py:441} INFO - ::group::Post task execution logs
[2024-05-08T19:44:17.092+0000] {taskinstance.py:2905} ERROR - Task failed with exception
Traceback (most recent call last):
  File "/home/airflow/.local/lib/python3.12/site-packages/airflow/models/taskinstance.py", line 465, in _execute_task
    result = _execute_callable(context=context, **execute_callable_kwargs)
             ^^^^^^^^^^^^^^^^^^^^^^^^^^^^^^^^^^^^^^^^^^^^^^^^^^^^^^^^^^^^^
  File "/home/airflow/.local/lib/python3.12/site-packages/airflow/models/taskinstance.py", line 432, in _execute_callable
    return execute_callable(context=context, **execute_callable_kwargs)
           ^^^^^^^^^^^^^^^^^^^^^^^^^^^^^^^^^^^^^^^^^^^^^^^^^^^^^^^^^^^^
  File "/home/airflow/.local/lib/python3.12/site-packages/airflow/models/baseoperator.py", line 400, in wrapper
    return func(self, *args, **kwargs)
           ^^^^^^^^^^^^^^^^^^^^^^^^^^^
  File "/home/airflow/.local/lib/python3.12/site-packages/airflow/operators/bash.py", line 243, in execute
    raise AirflowException(
airflow.exceptions.AirflowException: Bash command failed. The command returned a non-zero exit code 2.
[2024-05-08T19:44:17.095+0000] {taskinstance.py:1206} INFO - Marking task as FAILED. dag_id=7.3_filesensor, task_id=creating_file, run_id=scheduled__2022-07-09T00:00:00+00:00, execution_date=20220709T000000, start_date=20240508T194416, end_date=20240508T194417
[2024-05-08T19:44:17.112+0000] {standard_task_runner.py:110} ERROR - Failed to execute job 653 for task creating_file (Bash command failed. The command returned a non-zero exit code 2.; 1931)
[2024-05-08T19:44:17.135+0000] {local_task_job_runner.py:240} INFO - Task exited with return code 1
[2024-05-08T19:44:17.151+0000] {taskinstance.py:3498} INFO - 0 downstream tasks scheduled from follow-on schedule check
[2024-05-08T19:44:17.161+0000] {local_task_job_runner.py:222} INFO - ::endgroup::
